<?xml version="1.0"?>
<robot xmlns:xacro="http://www.ros.org/wiki/xacro">

    <xacro:property name="joint_damping" value="5.0"/>
  <xacro:property name="joint_friction" value="0.3"/>


   <link name="world"/>
    
  <joint
    name="J0"
    type="fixed">
    <origin
      xyz="0 0 0"
      rpy="0 0 0" />
    <parent
      link="world" />
    <child
      link="base_link" />
       <dynamics damping="${joint_damping}" friction="${joint_friction}"/>
  </joint>
<link
    name="base_link">
    <inertial>
      <origin
        xyz="0.00557 -1.2548E-06 0.094758"
        rpy="0 0 0" />
      <mass
        value="5.2154" />
      <inertia
        ixx="0.026026"
        ixy="0"
        ixz="0"
        iyy="0.025295"
        iyz="4.7704E-05"
        izz="0.02172" />
    </inertial>
    <visual>
      <origin
        xyz="0 0 0"
        rpy="0 0 0" />
      <geometry>
        <mesh
          filename="package://rarm/meshes/base_link.STL" />
      </geometry>
      <material
        name="">
        <color
          rgba="0.75294 0.75294 0.75294 1" />
      </material>
    </visual>
    <collision>
      <origin
        xyz="0 0 0"
        rpy="0 0 0" />
      <geometry>
        <mesh
          filename="package://rarm/meshes/base_link.STL" />
      </geometry>
    </collision>
  </link>
  <link
    name="L1">
    <inertial>
      <origin
        xyz="-0.015672 0.0001345 0.090428"
        rpy="0 0 0" />
      <mass
        value="2.9447" />
      <inertia
        ixx="0.011181"
        ixy="1.703E-06"
        ixz="0.0021793"
        iyy="0.011947"
        iyz="0"
        izz="0.0088687" />
    </inertial>
    <visual>
      <origin
        xyz="0 0 0"
        rpy="0 0 0" />
      <geometry>
        <mesh
          filename="package://rarm/meshes/L1.STL" />
      </geometry>
      <material
        name="">
        <color
          rgba="0.75294 0.75294 0.75294 1" />
      </material>
    </visual>
    <collision>
      <origin
        xyz="0 0 0"
        rpy="0 0 0" />
      <geometry>
        <mesh
          filename="package://rarm/meshes/L1.STL" />
      </geometry>
    </collision>
  </link>
  <joint
    name="J1"
    type="revolute">
    <origin
      xyz="0 0 0.19952"
      rpy="0 0 0" />
    <parent
      link="base_link" />
    <child
      link="L1" />
    <axis
      xyz="0 0 1" />
    <limit
      lower="-2.967"
      upper="2.967"
      effort="30"
      velocity="6.545" />
       <dynamics damping="${joint_damping}" friction="${joint_friction}"/>
  </joint>
  <link
    name="L2">
    <inertial>
      <origin
        xyz="0.027625 0.19499 0.00020193"
        rpy="0 0 0" />
      <mass
        value="6.2406" />
      <inertia
        ixx="0.1263"
        ixy="0.00019254"
        ixz="4.2906E-05"
        iyy="0.027757"
        iyz="0"
        izz="0.11052" />
    </inertial>
    <visual>
      <origin
        xyz="0 0 0"
        rpy="0 0 0" />
      <geometry>
        <mesh
          filename="package://rarm/meshes/L2.STL" />
      </geometry>
      <material
        name="">
        <color
          rgba="0.75294 0.75294 0.75294 1" />
      </material>
    </visual>
    <collision>
      <origin
        xyz="0 0 0"
        rpy="0 0 0" />
      <geometry>
        <mesh
          filename="package://rarm/meshes/L2.STL" />
      </geometry>
    </collision>
  </link>
  <joint
    name="J2"
    type="revolute">
    <origin
      xyz="-0.04 0 0.13048"
      rpy="1.5708 0 0" />
    <parent
      link="L1" />
    <child
      link="L2" />
    <axis
      xyz="0 0 -1" />
    <limit
      lower="-2.53"
      upper="1.135"
      effort="30"
      velocity="5.497" />
        <dynamics damping="${joint_damping}" friction="${joint_friction}"/>
  </joint>
  <link
    name="L3">
    <inertial>
      <origin
        xyz="-0.020055 -0.015909 0.00085391"
        rpy="0 0 0" />
      <mass
        value="2.8492" />
      <inertia
        ixx="0.0069342"
        ixy="0.00090368"
        ixz="0"
        iyy="0.0082319"
        iyz="0"
        izz="0.0077915" />
    </inertial>
    <visual>
      <origin
        xyz="0 0 0"
        rpy="0 0 0" />
      <geometry>
        <mesh
          filename="package://rarm/meshes/L3.STL" />
      </geometry>
      <material
        name="">
        <color
          rgba="0.75294 0.75294 0.75294 1" />
      </material>
    </visual>
    <collision>
      <origin
        xyz="0 0 0"
        rpy="0 0 0" />
      <geometry>
        <mesh
          filename="package://rarm/meshes/L3.STL" />
      </geometry>
    </collision>
  </link>
  <joint
    name="J3"
    type="revolute">
    <origin
      xyz="0 0.445 0"
      rpy="3.1416 0 -1.5708" />
    <parent
      link="L2" />
    <child
      link="L3" />
    <axis
      xyz="0 0 1" />
    <limit
      lower="-1.222"
      upper="3.316"
      effort="30"
      velocity="7.155" />
       <dynamics damping="${joint_damping}" friction="${joint_friction}"/>
  </joint>
  <link
    name="L4">
    <inertial>
      <origin
        xyz="0.00014939 0.00016036 0.24577"
        rpy="0 0 0" />
      <mass
        value="2.7554" />
      <inertia
        ixx="0.010085"
        ixy="0"
        ixz="0"
        iyy="0.010785"
        iyz="0.00031849"
        izz="0.0030857" />
    </inertial>
    <visual>
      <origin
        xyz="0 0 0"
        rpy="0 0 0" />
      <geometry>
        <mesh
          filename="package://rarm/meshes/L4.STL" />
      </geometry>
      <material
        name="">
        <color
          rgba="0.75294 0.75294 0.75294 1" />
      </material>
    </visual>
    <collision>
      <origin
        xyz="0 0 0"
        rpy="0 0 0" />
      <geometry>
        <mesh
          filename="package://rarm/meshes/L4.STL" />
      </geometry>
    </collision>
  </link>
  <joint
    name="J4"
    type="revolute">
    <origin
      xyz="-0.04 0 0"
      rpy="-1.5708 0 0" />
    <parent
      link="L3" />
    <child
      link="L4" />
    <axis
      xyz="0 0 1" />
    <limit
      lower="-3.316"
      upper="3.316"
      effort="30"
      velocity="9.599" />
       <dynamics damping="${joint_damping}" friction="${joint_friction}"/>
  </joint>
  <link
    name="L5">
    <inertial>
      <origin
        xyz="-0.00022335 0.01321 0.0017526"
        rpy="0 0 0" />
      <mass
        value="0.24589" />
      <inertia
        ixx="0.00013956"
        ixy="2.1399E-06"
        ixz="1.0002E-06"
        iyy="0.00015684"
        iyz="1.255E-06"
        izz="0.0001856" />
    </inertial>
    <visual>
      <origin
        xyz="0 0 0"
        rpy="0 0 0" />
      <geometry>
        <mesh
          filename="package://rarm/meshes/L5.STL" />
      </geometry>
      <material
        name="">
        <color
          rgba="0.75294 0.75294 0.75294 1" />
      </material>
    </visual>
    <collision>
      <origin
        xyz="0 0 0"
        rpy="0 0 0" />
      <geometry>
        <mesh
          filename="package://rarm/meshes/L5.STL" />
      </geometry>
    </collision>
  </link>
  <joint
    name="J5"
    type="revolute">
    <origin
      xyz="0 0 0.44"
      rpy="1.5708 0 0" />
    <parent
      link="L4" />
    <child
      link="L5" />
    <axis
      xyz="0.017452 0 0.99985" />
    <limit
      lower="-2.356"
      upper="2.356"
      effort="30"
      velocity="9.599" />
       <dynamics damping="${joint_damping}" friction="${joint_friction}"/>
  </joint>
  <link
    name="L6">
    <inertial>
      <origin
        xyz="-3.439E-12 9.8783E-13 0.096386"
        rpy="0 0 0" />
      <mass
        value="0.076892" />
      <inertia
        ixx="3.8067E-05"
        ixy="2.1708E-22"
        ixz="4.2198E-21"
        iyy="3.2045E-05"
        iyz="0"
        izz="4.0209E-05" />
    </inertial>
    <visual>
      <origin
        xyz="0 0 0"
        rpy="0 0 0" />
      <geometry>
        <mesh
          filename="package://rarm/meshes/L6.STL" />
      </geometry>
      <material
        name="">
        <color
          rgba="0.68627 0.60784 0.52941 1" />
      </material>
    </visual>
    <collision>
      <origin
        xyz="0 0 0"
        rpy="0 0 0" />
      <geometry>
        <mesh
          filename="package://rarm/meshes/L6.STL" />
      </geometry>
    </collision>
  </link>
  <joint
    name="J6"
    type="revolute">
    <origin
      xyz="0 0 0"
      rpy="-1.5708 0 0" />
    <parent
      link="L5" />
    <child
      link="L6" />
    <axis
      xyz="0 0 1" />
    <limit
      lower="0"
      upper="6.2832"
      effort="30"
      velocity="17.453" />
       <dynamics damping="${joint_damping}" friction="${joint_friction}"/>
  </joint>
  <link
    name="L7">
    <inertial>
      <origin
        xyz="0.015494 0.057693 0"
        rpy="0 0 0" />
      <mass
        value="0.040444" />
      <inertia
        ixx="5.0254E-05"
        ixy="0"
        ixz="2.7312E-21"
        iyy="4.2537E-06"
        iyz="1.2972E-20"
        izz="5.2363E-05" />
    </inertial>
    <visual>
      <origin
        xyz="0 0 0"
        rpy="0 0 0" />
      <geometry>
        <mesh
          filename="package://rarm/meshes/L7.STL" />
      </geometry>
      <material
        name="">
        <color
          rgba="0.6902 0.61176 0.52941 1" />
      </material>
    </visual>
    <collision>
      <origin
        xyz="0 0 0"
        rpy="0 0 0" />
      <geometry>
        <mesh
          filename="package://rarm/meshes/L7.STL" />
      </geometry>
    </collision>
  </link>
  <joint
    name="J7"
    type="revolute">
    <origin
      xyz="0 0.044379 0.11015"
      rpy="1.5708 0 -1.5708" />
    <parent
      link="L6" />
    <child
      link="L7" />
    <axis
      xyz="0 0 -1" />
    <limit
      lower="-1.57"
      upper="0"
      effort="30"
      velocity="10" />
       <dynamics damping="${joint_damping}" friction="${joint_friction}"/>
  </joint>
  <link
    name="L8">
    <inertial>
      <origin
        xyz="-0.015494 0.057693 -1.1102E-16"
        rpy="0 0 0" />
      <mass
        value="0.040444" />
      <inertia
        ixx="5.0254E-05"
        ixy="5.3227E-06"
        ixz="0"
        iyy="4.2537E-06"
        iyz="1.4329E-20"
        izz="5.2363E-05" />
    </inertial>
    <visual>
      <origin
        xyz="0 0 0"
        rpy="0 0 0" />
      <geometry>
        <mesh
          filename="package://rarm/meshes/L8.STL" />
      </geometry>
      <material
        name="">
        <color
          rgba="0.6902 0.61176 0.52941 1" />
      </material>
    </visual>
    <collision>
      <origin
        xyz="0 0 0"
        rpy="0 0 0" />
      <geometry>
        <mesh
          filename="package://rarm/meshes/L8.STL" />
      </geometry>
    </collision>
  </link>
  <joint
    name="J8"
    type="revolute">
    <origin
      xyz="0 -0.044379 0.11015"
      rpy="1.5708 0 -1.5708" />
    <parent
      link="L6" />
    <child
      link="L8" />
    <axis
      xyz="0 0 1" />
    <limit
      lower="-1.57"
      upper="0"
      effort="30"
      velocity="10" />
      <mimic joint="J7" multiplier="1.0" offset="0"/>
       <dynamics damping="${joint_damping}" friction="${joint_friction}"/>
  </joint>

  </robot>